<?xml version="1.0" ?>
<!-- =================================================================================== -->
<!-- |    This document was autogenerated by xacro from urdf/shelfbot.urdf.xacro       | -->
<!-- |    EDITING THIS FILE BY HAND IS NOT RECOMMENDED                                 | -->
<!-- =================================================================================== -->
<robot name="shelfbot">
  <!-- Material Definitions -->
  <material name="gray">
    <color rgba="0.5 0.5 0.5 1"/>
  </material>
  <material name="black">
    <color rgba="0 0 0 1"/>
  </material>
  <!-- Base Link -->
  <link name="base_link">
    <visual>
      <geometry>
        <box size="0.5 0.3 0.1"/>
      </geometry>
      <material name="gray"/>
    </visual>
    <collision>
      <geometry>
        <box size="0.5 0.3 0.1"/>
      </geometry>
    </collision>
    <inertial>
      <mass value="10"/>
      <origin rpy="0 0 0" xyz="0 0 0"/>
      <inertia ixx="0.1" ixy="0.0" ixz="0.0" iyy="0.1" iyz="0.0" izz="0.1"/>
    </inertial>
  </link>
  <link name="front_left_motor">
    <visual>
      <geometry>
        <cylinder length="0.05" radius="0.1"/>
      </geometry>
      <material name="black"/>
    </visual>
    <collision>
      <geometry>
        <cylinder length="0.05" radius="0.1"/>
      </geometry>
    </collision>
    <inertial>
      <mass value="1.0"/>
      <origin rpy="0 0 0" xyz="0 0 0"/>
      <inertia ixx="0.01" ixy="0.0" ixz="0.0" iyy="0.01" iyz="0.0" izz="0.01"/>
    </inertial>
  </link>
  <link name="front_right_motor">
    <visual>
      <geometry>
        <cylinder length="0.05" radius="0.1"/>
      </geometry>
      <material name="black"/>
    </visual>
    <collision>
      <geometry>
        <cylinder length="0.05" radius="0.1"/>
      </geometry>
    </collision>
    <inertial>
      <mass value="1.0"/>
      <origin rpy="0 0 0" xyz="0 0 0"/>
      <inertia ixx="0.01" ixy="0.0" ixz="0.0" iyy="0.01" iyz="0.0" izz="0.01"/>
    </inertial>
  </link>
  <link name="rear_left_motor">
    <visual>
      <geometry>
        <cylinder length="0.05" radius="0.1"/>
      </geometry>
      <material name="black"/>
    </visual>
    <collision>
      <geometry>
        <cylinder length="0.05" radius="0.1"/>
      </geometry>
    </collision>
    <inertial>
      <mass value="1.0"/>
      <origin rpy="0 0 0" xyz="0 0 0"/>
      <inertia ixx="0.01" ixy="0.0" ixz="0.0" iyy="0.01" iyz="0.0" izz="0.01"/>
    </inertial>
  </link>
  <link name="rear_right_motor">
    <visual>
      <geometry>
        <cylinder length="0.05" radius="0.1"/>
      </geometry>
      <material name="black"/>
    </visual>
    <collision>
      <geometry>
        <cylinder length="0.05" radius="0.1"/>
      </geometry>
    </collision>
    <inertial>
      <mass value="1.0"/>
      <origin rpy="0 0 0" xyz="0 0 0"/>
      <inertia ixx="0.01" ixy="0.0" ixz="0.0" iyy="0.01" iyz="0.0" izz="0.01"/>
    </inertial>
  </link>
  <!-- Wheels -->
  <link name="front_left_wheel">
    <visual>
      <geometry>
        <cylinder length="0.05" radius="0.1"/>
      </geometry>
      <material name="black"/>
    </visual>
    <collision>
      <geometry>
        <cylinder length="0.05" radius="0.1"/>
      </geometry>
    </collision>
  </link>
  <link name="front_right_wheel">
    <visual>
      <geometry>
        <cylinder length="0.05" radius="0.1"/>
      </geometry>
      <material name="black"/>
    </visual>
    <collision>
      <geometry>
        <cylinder length="0.05" radius="0.1"/>
      </geometry>
    </collision>
  </link>
  <link name="rear_left_wheel">
    <visual>
      <geometry>
        <cylinder length="0.05" radius="0.1"/>
      </geometry>
      <material name="black"/>
    </visual>
    <collision>
      <geometry>
        <cylinder length="0.05" radius="0.1"/>
      </geometry>
    </collision>
  </link>
  <link name="rear_right_wheel">
    <visual>
      <geometry>
        <cylinder length="0.05" radius="0.1"/>
      </geometry>
      <material name="black"/>
    </visual>
    <collision>
      <geometry>
        <cylinder length="0.05" radius="0.1"/>
      </geometry>
    </collision>
  </link>
  <!-- Camera -->
  <link name="camera_link">
    <visual>
      <geometry>
        <box size="0.2 0.2 0.1"/>
        <cylinder length="0.05" radius="0.1"/>
      </geometry>
      <material name="gray"/>
    </visual>
    <collision>
      <geometry>
        <box size="0.2 0.2 0.1"/>
        <cylinder length="0.05" radius="0.1"/>
      </geometry>
    </collision>
  </link>
  <!-- Joints -->
  <joint name="front_left_motor_joint" type="revolute">
    <parent link="base_link"/>
    <child link="front_left_motor"/>
    <origin xyz="0.25 0.2 0"/>
    <axis xyz="0 1 0"/>
    <limit effort="30" velocity="1.0"/>
  </joint>
  <joint name="front_right_motor_joint" type="revolute">
    <parent link="base_link"/>
    <child link="front_right_motor"/>
    <origin xyz="0.25 -0.2 0"/>
    <axis xyz="0 1 0"/>
    <limit effort="30" velocity="1.0"/>
  </joint>
  <joint name="rear_left_motor_joint" type="revolute">
    <parent link="base_link"/>
    <child link="rear_left_motor"/>
    <origin xyz="-0.25 0.2 0"/>
    <axis xyz="0 1 0"/>
    <limit effort="30" velocity="1.0"/>
  </joint>
  <joint name="rear_right_motor_joint" type="revolute">
    <parent link="base_link"/>
    <child link="rear_right_motor"/>
    <origin xyz="-0.25 -0.2 0"/>
    <axis xyz="0 1 0"/>
    <limit effort="30" velocity="1.0"/>
  </joint>
  <!-- Attach wheels to motors -->
  <joint name="front_left_wheel_joint" type="fixed">
    <parent link="front_left_motor"/>
    <child link="front_left_wheel"/>
    <origin xyz="0 0 0"/>
  </joint>
  <joint name="front_right_wheel_joint" type="fixed">
    <parent link="front_right_motor"/>
    <child link="front_right_wheel"/>
    <origin xyz="0 0 0"/>
  </joint>
  <joint name="rear_left_wheel_joint" type="fixed">
    <parent link="rear_left_motor"/>
    <child link="rear_left_wheel"/>
    <origin xyz="0 0 0"/>
  </joint>
  <joint name="rear_right_wheel_joint" type="fixed">
    <parent link="rear_right_motor"/>
    <child link="rear_right_wheel"/>
    <origin xyz="0 0 0"/>
  </joint>
  <!-- Attach camera to base_link -->
  <joint name="camera_joint" type="fixed">
    <parent link="base_link"/>
    <child link="camera_link"/>
    <origin xyz="0 0 0.3"/>
  </joint>
</robot>
