<?xml version="1.0"?>
<robot xmlns:xacro="http://www.ros.org/wiki/xacro" name="shelfbot">

  <!-- ═══════════════════════════════════════════════════════════════════
       Single source of truth: all materials, properties and inertia
       macros live in common_properties.xacro.  Nothing is duplicated here.
       ═══════════════════════════════════════════════════════════════════ -->
  <xacro:include filename="$(find shelfbot)/urdf/common_properties.xacro"/>

  <!-- ═══════════════════════════════════════════════════════════════════
       Component macros
       ═══════════════════════════════════════════════════════════════════ -->
  <xacro:include filename="$(find shelfbot)/urdf/motor.xacro"/>
  <xacro:include filename="$(find shelfbot)/urdf/wheel.xacro"/>
  <xacro:include filename="$(find shelfbot)/urdf/camera.xacro"/>
  <xacro:include filename="$(find shelfbot)/urdf/base_axis.xacro"/>
  <xacro:include filename="$(find shelfbot)/urdf/ultrasonic_sensor.xacro"/>

  <!-- ═══════════════════════════════════════════════════════════════════
       Launch-file arguments (config is already loaded by common_properties)
       ═══════════════════════════════════════════════════════════════════ -->
  <xacro:arg name="base_url"            default="http://shelfbot.local/"/>
  <xacro:arg name="communication_type"  default="${str(config['controller_manager']['ros__parameters']['hardware_interface']['communication_type'])}"/>
  <xacro:arg name="wheel_separation"    default="${str(config['four_wheel_drive_controller']['ros__parameters']['wheel_separation'])}"/>
  <xacro:arg name="wheel_radius"        default="${str(config['four_wheel_drive_controller']['ros__parameters']['wheel_radius'])}"/>

  <!-- ═══════════════════════════════════════════════════════════════════
       ros2_control hardware interface (real robot)
       ═══════════════════════════════════════════════════════════════════ -->
  <xacro:include filename="$(find shelfbot)/urdf/real.robot.urdf.xacro"/>

  <!-- ═══════════════════════════════════════════════════════════════════
       Robot physical structure
       ═══════════════════════════════════════════════════════════════════ -->

  <!-- Root link — no inertial, no visual: required by REP 120 -->
  <link name="base_footprint"/>

  <link name="base_link">
    <visual>
      <geometry>
        <box size="${base_width} ${base_length} ${base_height}"/>
      </geometry>
      <material name="golden_brown"/>
    </visual>
    <collision>
      <geometry>
        <box size="${base_width} ${base_length} ${base_height}"/>
      </geometry>
    </collision>
    <inertial>
      <mass value="${base_mass}"/>
      <origin xyz="0 0 0" rpy="0 0 0"/>
      <xacro:box_inertia m="${base_mass}" x="${base_width}" y="${base_length}" z="${base_height}"/>
    </inertial>
  </link>

  <!-- base_footprint sits on the ground; base_link centre is raised by
       half its height plus one wheel radius -->
  <joint name="joint_base_footprint" type="fixed">
    <parent link="base_footprint"/>
    <child link="base_link"/>
    <origin xyz="0 0 ${base_height/2 + wheel_radius}" rpy="0 0 0"/>
  </joint>

  <!-- ── Motors (fixed to base_link) ───────────────────────────────── -->
  <xacro:motor name="motor_front_left"  length="${motor_length}" radius="${motor_radius}"/>
  <xacro:motor name="motor_front_right" length="${motor_length}" radius="${motor_radius}"/>
  <xacro:motor name="motor_back_left"   length="${motor_length}" radius="${motor_radius}"/>
  <xacro:motor name="motor_back_right"  length="${motor_length}" radius="${motor_radius}"/>

  <!-- Left motors: rpy="pi/2 0 pi"   → shaft exits toward -Y (left side)
       Right motors: rpy="-pi/2 0 0"  → shaft exits toward +Y (right side) -->
  <joint name="joint_motor_front_left" type="fixed">
    <parent link="base_link"/>
    <child link="motor_front_left"/>
    <origin xyz="${-base_width/2 + motor_length} ${base_length/2 - 0.075} 0"
            rpy="${pi/2} 0 ${pi}"/>
  </joint>

  <joint name="joint_motor_front_right" type="fixed">
    <parent link="base_link"/>
    <child link="motor_front_right"/>
    <origin xyz="${base_width/2 - motor_length} ${base_length/2 - 0.075} 0"
            rpy="${-pi/2} 0 0"/>
  </joint>

  <joint name="joint_motor_back_left" type="fixed">
    <parent link="base_link"/>
    <child link="motor_back_left"/>
    <origin xyz="${-base_width/2 + motor_length} ${-base_length/2 + 0.075} 0"
            rpy="${pi/2} 0 ${pi}"/>
  </joint>

  <joint name="joint_motor_back_right" type="fixed">
    <parent link="base_link"/>
    <child link="motor_back_right"/>
    <origin xyz="${base_width/2 - motor_length} ${-base_length/2 + 0.075} 0"
            rpy="${-pi/2} 0 0"/>
  </joint>

  <!-- ── Drive axles (continuous, controlled by ros2_control) ──────── -->
  <xacro:base_axis name="base_axis_front_left"  length="${base_axis_length}" radius="${base_axis_radius}"/>
  <xacro:base_axis name="base_axis_front_right" length="${base_axis_length}" radius="${base_axis_radius}"/>
  <xacro:base_axis name="base_axis_back_left"   length="${base_axis_length}" radius="${base_axis_radius}"/>
  <xacro:base_axis name="base_axis_back_right"  length="${base_axis_length}" radius="${base_axis_radius}"/>

  <!-- Left axles rotate around local +X, offset by -pi/2 from motor frame -->
  <joint name="joint_base_axis_front_left" type="continuous">
    <parent link="motor_front_left"/>
    <child link="base_axis_front_left"/>
    <origin xyz="0 0 0" rpy="${-pi/2} 0 0"/>
    <axis xyz="1 0 0"/>
    <dynamics damping="${joint_damping}" friction="${joint_friction}"/>
  </joint>

  <joint name="joint_base_axis_front_right" type="continuous">
    <parent link="motor_front_right"/>
    <child link="base_axis_front_right"/>
    <origin xyz="0 0 0" rpy="${pi/2} 0 0"/>
    <axis xyz="1 0 0"/>
    <dynamics damping="${joint_damping}" friction="${joint_friction}"/>
  </joint>

  <joint name="joint_base_axis_back_left" type="continuous">
    <parent link="motor_back_left"/>
    <child link="base_axis_back_left"/>
    <origin xyz="0 0 0" rpy="${-pi/2} 0 0"/>
    <axis xyz="1 0 0"/>
    <dynamics damping="${joint_damping}" friction="${joint_friction}"/>
  </joint>

  <joint name="joint_base_axis_back_right" type="continuous">
    <parent link="motor_back_right"/>
    <child link="base_axis_back_right"/>
    <origin xyz="0 0 0" rpy="${pi/2} 0 0"/>
    <axis xyz="1 0 0"/>
    <dynamics damping="${joint_damping}" friction="${joint_friction}"/>
  </joint>

  <!-- ── Wheels (fixed to axles) ───────────────────────────────────── -->
  <xacro:wheel name="wheel_front_left"  radius="${wheel_radius}" width="${wheel_width}"/>
  <xacro:wheel name="wheel_front_right" radius="${wheel_radius}" width="${wheel_width}"/>
  <xacro:wheel name="wheel_back_left"   radius="${wheel_radius}" width="${wheel_width}"/>
  <xacro:wheel name="wheel_back_right"  radius="${wheel_radius}" width="${wheel_width}"/>

  <!-- Wheel inner face aligns with axle tip:
       offset = base_width/2 - motor_length (must equal base_axis_length) -->
  <joint name="joint_wheel_front_left" type="fixed">
    <parent link="base_axis_front_left"/>
    <child link="wheel_front_left"/>
    <origin xyz="${base_width/2 - motor_length} 0 0" rpy="0 0 0"/>
  </joint>

  <joint name="joint_wheel_front_right" type="fixed">
    <parent link="base_axis_front_right"/>
    <child link="wheel_front_right"/>
    <origin xyz="${base_width/2 - motor_length} 0 0" rpy="0 0 0"/>
  </joint>

  <joint name="joint_wheel_back_left" type="fixed">
    <parent link="base_axis_back_left"/>
    <child link="wheel_back_left"/>
    <origin xyz="${base_width/2 - motor_length} 0 0" rpy="0 0 0"/>
  </joint>

  <joint name="joint_wheel_back_right" type="fixed">
    <parent link="base_axis_back_right"/>
    <child link="wheel_back_right"/>
    <origin xyz="${base_width/2 - motor_length} 0 0" rpy="0 0 0"/>
  </joint>

  <!-- ── Camera ────────────────────────────────────────────────────── -->
  <!--
    camera.xacro creates two links: camera_link and camera_link_optical_frame.
    After joint_camera (rpy="-pi/2 0 0") camera_link axes in base_link space:
      +Z = base_link +Y (forward / optical axis)
      +X = base_link +X (right)
      +Y = base_link -Z (down)
    camera_link is therefore already in ROS optical convention.
    camera_link_optical_frame adds the standard rpy="-pi/2 0 -pi/2" child for
    image_pipeline / rtabmap compatibility.
    The camera_publisher frame_id parameter must be "camera_link_optical_frame".
  -->
  <xacro:camera name="camera_link"
                width="${camera_width}"
                length="${camera_length}"
                height="${camera_height}"/>

  <joint name="joint_camera" type="fixed">
    <parent link="base_link"/>
    <child link="camera_link"/>
    <!-- Centred on top face of base_link, facing forward (+Y) -->
    <origin xyz="0 0 ${base_height}" rpy="${-pi/2} 0 0"/>
  </joint>

  <!-- ── Ultrasonic sensors (3 front, 3 back) ──────────────────────── -->
  <xacro:ultrasonic_sensor name="us_front_center"/>
  <xacro:ultrasonic_sensor name="us_front_left_corner"/>
  <xacro:ultrasonic_sensor name="us_front_right_corner"/>
  <xacro:ultrasonic_sensor name="us_back_center"/>
  <xacro:ultrasonic_sensor name="us_back_left_corner"/>
  <xacro:ultrasonic_sensor name="us_back_right_corner"/>

  <!-- Front sensors: rpy="0 pi/2 angle" orients PCB face outward -->
  <joint name="joint_us_front_center" type="fixed">
    <parent link="base_link"/>
    <child link="us_front_center"/>
    <origin xyz="0 ${base_length/2} ${ultrasonic_z_offset}"
            rpy="0 ${pi/2} ${pi/2}"/>
  </joint>

  <joint name="joint_us_front_left_corner" type="fixed">
    <parent link="base_link"/>
    <child link="us_front_left_corner"/>
    <origin xyz="${base_width/4} ${base_length/2} ${ultrasonic_z_offset}"
            rpy="0 ${pi/2} ${pi/4}"/>
  </joint>

  <joint name="joint_us_front_right_corner" type="fixed">
    <parent link="base_link"/>
    <child link="us_front_right_corner"/>
    <origin xyz="${-base_width/4} ${base_length/2} ${ultrasonic_z_offset}"
            rpy="0 ${pi/2} ${3*pi/4}"/>
  </joint>

  <!-- Back sensors -->
  <joint name="joint_us_back_center" type="fixed">
    <parent link="base_link"/>
    <child link="us_back_center"/>
    <origin xyz="0 ${-base_length/2} ${ultrasonic_z_offset}"
            rpy="0 ${pi/2} ${-pi/2}"/>
  </joint>

  <joint name="joint_us_back_left_corner" type="fixed">
    <parent link="base_link"/>
    <child link="us_back_left_corner"/>
    <origin xyz="${base_width/4} ${-base_length/2} ${ultrasonic_z_offset}"
            rpy="0 ${pi/2} ${-pi/4}"/>
  </joint>

  <joint name="joint_us_back_right_corner" type="fixed">
    <parent link="base_link"/>
    <child link="us_back_right_corner"/>
    <origin xyz="${-base_width/4} ${-base_length/2} ${ultrasonic_z_offset}"
            rpy="0 ${pi/2} ${-3*pi/4}"/>
  </joint>

</robot>
